<?xml version="1.0"?>

<robot xmlns:xacro="http://www.ros.org/wiki/xacro">
  <!-- Main quadrotor link -->
  <xacro:macro name="velodyne">
		<link name="mx64"> </link>
	  <link name="velodyne"></link>
	  <link name="velodyne_aligned"></link>
	   <link name="velodyne_link">
	      <inertial>
	        <mass value="0.1"/>
	        <origin xyz="0 0 0"/>
	        <inertia ixx="0.1" ixy="0" ixz="0" iyy="0.1" iyz="0" izz="0.1"/>
	      </inertial>
	      <collision>
	        <origin rpy="0 0 0" xyz="0 0 0.03585"/>
	        <geometry>
	          <cylinder radius="0.0516" length="0.0717"/>
	        </geometry>
	      </collision>
	    </link>
			<joint name="tilt_joint" type="revolute">
	 			<origin xyz="0.25 0.0 -0.1" rpy="0 ${-M_PI} ${-M_PI}" />
	 			 <parent link="base_link"/>
	 			<child link="mx64" />
	 			<axis xyz="0 1 0" />
	 			<limit lower="-1.57" upper="1.57" effort="30" velocity="1.6" />
	 	 </joint>
	 	 <joint name="mx64_to_vlp" type="fixed">
	 			<origin xyz="0.0 0 0.1" rpy="0 0 -0.01" />
	 			<parent link="mx64" />
	 			<child link="velodyne_link"/>
	 	 </joint>
	 	 <joint name="velodyne_joint" type="fixed" >
	 				 <origin xyz="0 0 0.0377" rpy="0 0 0" />
	 				 <parent link="velodyne_link" />
	 				 <child link="velodyne"/>
			 </joint>
	     <joint name="velodyne_joint_aligned" type="fixed" >
	           <origin xyz="0 0 0.0" rpy="0 ${-M_PI} ${-M_PI}" />
	           <parent link="velodyne_link" />
	           <child link="velodyne_aligned"/>
	     </joint>
  </xacro:macro>
</robot>
